<?xml version="1.0" ?>
<robot name="moveo_urdf">


  <link name="world"/>

    <joint name="fixed" type="fixed">
	<parent link="world"/>
	<child link="base_link"/>
	<origin xyz="0 0 0" rpy="0 0 0" />
    </joint>

    <link name="base_link">
        <visual>
            <origin xyz="0 0.24 .13" rpy="0 0 0" />
            <geometry>
                <mesh filename="package://moveo_urdf/meshes/base_link.STL" />
            </geometry>
            <material name="">
                <color rgba="0.75294 0.75294 0.75294 1" />
            </material>
        </visual>
        <collision>
            <origin xyz="0 0 .13" rpy="0 0 0" />
            <geometry>
                <mesh filename="package://moveo_urdf/meshes/base_link_col.STL" />
            </geometry>
        </collision>        
	<inertial>
            <mass value="0.1" />
            <inertia ixx="0.03" iyy="0.03" izz="0.03" ixy="0.0" ixz="0.0" iyz="0.0" />
        </inertial>
    </link>

    <joint name="Joint_1" type="revolute">
	<origin xyz="0 0 .13" rpy="0 0 0" />
        <axis xyz="0 0 1" />
        <limit lower="-1.5707963268" upper="1.5707963268" effort="100" velocity="1.919862177191" />
        <parent link="base_link" />
        <child link="Link_1" />
    </joint>

    <link name="Link_1">
        <visual>
            <origin xyz="0 0 0" rpy="0 0 0" />
            <geometry>
		<mesh filename="package://moveo_urdf/meshes/Link_1_edited.STL" />
            </geometry>
            <material name="">
                <color rgba="0.75294 0.75294 0.75294 1" />
            </material>
        </visual>
        <collision>
            <origin xyz="0 0 0" rpy="0 0 0" />
            <geometry>        
		<mesh filename="package://moveo_urdf/meshes/Link_1_edited.STL" />
            </geometry>
        </collision>
	<inertial>
            <mass value="0.1" />
            <inertia ixx="0.03" iyy="0.03" izz="0.03" ixy="0.0" ixz="0.0" iyz="0.0" />
        </inertial>
    </link>

    <link name="Link_2">
        <visual>
            <origin xyz="0 0 0" rpy="0 0 0" />
            <geometry>
            	<mesh filename="package://moveo_urdf/meshes/Link_2_edited.STL" />
            </geometry>
            <material name="">
                <color rgba="0.75294 0.75294 0.75294 1" />
            </material>
        </visual>
        <collision>
            <origin xyz="0 0 0" rpy="0 0 0" />
            <geometry>
            	<mesh filename="package://moveo_urdf/meshes/Link_2_edited.STL" />
            </geometry>
        </collision>
        
	<inertial>
            <mass value="0.1" />
            <inertia ixx="0.03" iyy="0.03" izz="0.03" ixy="0.0" ixz="0.0" iyz="0.0" />
        </inertial>

    </link>
    <joint name="Joint_2" type="revolute">
        <origin xyz="0 0 0.18264" rpy="0 0 0" />
        <parent link="Link_1" />
        <child link="Link_2" />
        <axis xyz="1 0 0" />
        <limit lower="-1.5707963268" upper="1.5707963268" effort="100" velocity="1.919862177191" />
    </joint>

    <link name="Link_3">
        <visual>
            <origin xyz="0 0 0" rpy="0 0 0" />
            <geometry>
		<mesh filename="package://moveo_urdf/meshes/Link_3_edited.STL" />
            </geometry>
            <material name="">
                <color rgba="0.75294 0.75294 0.75294 1" />
            </material>
        </visual>
        <collision>
            <origin xyz="0 0 0" rpy="0 0 0" />
            <geometry>
		<mesh filename="package://moveo_urdf/meshes/Link_3_edited.STL" />
            </geometry>
        </collision>
        
	<inertial>
            <mass value="0.1" />
            <inertia ixx="0.03" iyy="0.03" izz="0.03" ixy="0.0" ixz="0.0" iyz="0.0" />
        </inertial>

    </link>
    <joint name="Joint_3" type="revolute">
        <origin xyz="0 0 0.22" rpy="0 0 0" />
        <parent link="Link_2" />
        <child link="Link_3" />
        <axis xyz="1 0 0" />
        <limit lower="-1.5707963268" upper="1.5707963268" effort="100" velocity="1.919862177191" />
    </joint>

    <link name="Link_4">
        <visual>
            <origin xyz="0 0 0" rpy="0 0 0" />
            <geometry>
		<mesh filename="package://moveo_urdf/meshes/Link_4_edited.STL" />
            </geometry>
            <material name="">
                <color rgba="0.75294 0.75294 0.75294 1" />
            </material>
        </visual>
        <collision>
            <origin xyz="0 0 0" rpy="0 0 0" />
            <geometry>
		<mesh filename="package://moveo_urdf/meshes/Link_4_edited.STL" />
            </geometry>
        </collision>
        
	<inertial>
            <mass value="0.1" />
            <inertia ixx="0.03" iyy="0.03" izz="0.03" ixy="0.0" ixz="0.0" iyz="0.0" />
        </inertial>

    </link>
    <joint name="Joint_4" type="revolute">
        <origin xyz="0.001 -0.002 0.16988" rpy="0 0 0.0872664626" />
        <parent link="Link_3" />
        <child link="Link_4" />
        <axis xyz="0 0 1" />
        <limit lower="-1.5707963268" upper="1.5707963268" effort="100" velocity="1.919862177191" />
    </joint>

    <link name="Link_5">
        <visual>
            <origin xyz="0 0 0" rpy="0 0 0" />
            <geometry>
		<mesh filename="package://moveo_urdf/meshes/Link_5_edited.STL" />
            </geometry>
            <material name="">
                <color rgba="0.75294 0.75294 0.75294 1" />
            </material>
        </visual>
        <collision>
            <origin xyz="0 0 0" rpy="0 0 0" />
            <geometry>
		<mesh filename="package://moveo_urdf/meshes/Link_5_edited.STL" />
            </geometry>
        </collision>
        
	<inertial>
            <mass value="0.1" />
            <inertia ixx="0.03" iyy="0.03" izz="0.03" ixy="0.0" ixz="0.0" iyz="0.0" />
        </inertial>

    </link>
    <joint name="Joint_5" type="revolute">
        <origin xyz="-0.002 0.001 0.055" rpy="0 0 -0.0872664626" />
        <parent link="Link_4" />
        <child link="Link_5" />
        <axis xyz="1 0 0" />
        <limit lower="-1.5707963268" upper="1.5707963268" effort="100" velocity="1.919862177191" />
    </joint>

    <link name="Gripper_Servo_Gear">
        <visual>
            <origin xyz="0 0 0" rpy="0 0 0" />
            <geometry>
                <mesh filename="package://moveo_urdf/meshes/Gripper_Servo_Gear.STL" />
            </geometry>
            <material name="">
                <color rgba="0.9098 0.44314 0.031373 1" />
            </material>
        </visual>
        <collision>
            <origin xyz="0 0 0" rpy="0 0 0" />
            <geometry>
                <mesh filename="package://moveo_urdf/meshes/Gripper_Servo_Gear_col.STL" />
            </geometry>
        </collision>
        
	<inertial>
            <mass value="0.1" />
            <inertia ixx="0.03" iyy="0.03" izz="0.03" ixy="0.0" ixz="0.0" iyz="0.0" />
        </inertial>
    </link>

    <joint name="Gripper_Servo_Gear_Joint" type="revolute">
        <origin xyz="-0.012 0 0.065" rpy="0 0.032705 0" />
        <parent link="Link_5" />
        <child link="Gripper_Servo_Gear" />
        <axis xyz="0 1 0" />
        <limit lower="0" upper="1.5707963268" effort="100" velocity="0.5" />
    </joint>

    <link name="Gripper_Idol_Gear">
        <visual>
            <origin xyz="0 0 0" rpy="0 0 0" />
            <geometry>
                <mesh filename="package://moveo_urdf/meshes/Gripper_Idol_Gear.STL" />
            </geometry>
            <material name="">
                <color rgba="0.058824 0.64706 1 1" />
            </material>
        </visual>
        <collision>
            <origin xyz="0 0 0" rpy="0 0 0" />
            <geometry>
                <mesh filename="package://moveo_urdf/meshes/Gripper_Idol_Gear_col.STL" />
            </geometry>
        </collision>
        
				<inertial>
            <mass value="0.1" />
            <inertia ixx="0.03" iyy="0.03" izz="0.03" ixy="0.0" ixz="0.0" iyz="0.0" />
        </inertial>

    </link>
    <joint name="Gripper_Idol_Gear_Joint" type="revolute">
        <origin xyz="0.012 0 0.065" rpy="3.1415926536 -0.040996 3.1415926536" />
        <parent link="Link_5" />
        <child link="Gripper_Idol_Gear" />
        <axis xyz="0 1 0" />
        <limit lower="-1.5707963268" upper="0" effort="100" velocity="0.5" />
    </joint>

    <link name="Tip_Gripper_Idol">
        <visual>
            <origin xyz="0 0 0" rpy="0 0 0" />
            <geometry>
                <mesh filename="package://moveo_urdf/meshes/Tip_Gripper_Idol.STL" />
            </geometry>
            <material name="">
                <color rgba="0.79216 0.81961 0.93333 1" />
            </material>
        </visual>
        <collision>
            <origin xyz="0 0 0" rpy="0 0 0" />
            <geometry>
                <mesh filename="package://moveo_urdf/meshes/Tip_Gripper_Idol_col.STL" />
            </geometry>
        </collision>
        
				<inertial>
            <mass value="0.1" />
            <inertia ixx="0.03" iyy="0.03" izz="0.03" ixy="0.0" ixz="0.0" iyz="0.0" />
        </inertial>

    </link>

    <link name="Tip_Gripper_Servo">
        <visual>
            <origin xyz="0 0 0" rpy="0 0 0" />
            <geometry>
                <mesh filename="package://moveo_urdf/meshes/Tip_Gripper_Servo.STL" />
            </geometry>
            <material name="">
                <color rgba="0.6 1 0.27843 1" />
            </material>
        </visual>
        <collision>
            <origin xyz="0 0 0" rpy="0 0 0" />
            <geometry>
                <mesh filename="package://moveo_urdf/meshes/Tip_Gripper_Servo_col.STL" />
            </geometry>
        </collision>
        
				<inertial>
            <mass value="0.1" />
            <inertia ixx="0.03" iyy="0.03" izz="0.03" ixy="0.0" ixz="0.0" iyz="0.0" />
        </inertial>

    </link>

    <joint name="Tip_Gripper_Servo_Joint" type="revolute">
        <origin xyz="-0.039906 -0.004 -0.0027473" rpy="-3.1416 -1.5569 -2.0392E-12" />
        <parent link="Gripper_Servo_Gear" />
        <child link="Tip_Gripper_Servo" />
        <axis xyz="0 1 0" />
        <limit lower="0" upper="1.3" effort="100" velocity="0.5" />
        <mimic joint="Gripper_Servo_Gear_Joint" multiplier="1" offset="0" />
    </joint>

    <joint name="Tip_Gripper_Idol_Joint" type="revolute">
        <origin xyz="-0.039906 -0.000125 -0.0027473" rpy="3.1416 0.5236 3.1416" />
        <parent link="Gripper_Idol_Gear" />
        <child link="Tip_Gripper_Idol" />
        <axis xyz="0 1 0" />
        <limit lower="3.14" upper="-3.14" effort="100" velocity="0.5" />
        <mimic joint="Gripper_Idol_Gear_Joint" multiplier="-1" offset="0" />
    </joint>


    <link name="Pivot_Arm_Gripper_Servo">
        <visual>
            <origin xyz="0 0 0" rpy="0 0 0" />
            <geometry>
                <mesh filename="package://moveo_urdf/meshes/Pivot_Arm_Gripper_Servo.STL" />
            </geometry>
            <material name="">
                <color rgba="0.79216 0.81961 0.93333 1" />
            </material>
        </visual>
        <collision>
            <origin xyz="0 0 0" rpy="0 0 0" />
            <geometry>
                <mesh filename="package://moveo_urdf/meshes/Pivot_Arm_Gripper_Servo_col.STL" />
            </geometry>
        </collision>
        
				<inertial>
            <mass value="0.1" />
            <inertia ixx="0.03" iyy="0.03" izz="0.03" ixy="0.0" ixz="0.0" iyz="0.0" />
        </inertial>

    </link>
    <joint name="Pivot_Arm_Gripper_Servo_Joint" type="revolute">
        <origin xyz="-0.005 0 0.085" rpy="0 -0.0083007 0" />
        <parent link="Link_5" />
        <child link="Pivot_Arm_Gripper_Servo" />
        <axis xyz="0 1 0" />
        <limit lower="-1.5707963268" upper="1.5707963268" effort="100" velocity="0.5" />
        <mimic joint="Gripper_Servo_Gear_Joint" multiplier="1" offset="0" />
    </joint>

    <link name="Pivot_Arm_Gripper_Idol">
        <visual>
            <origin xyz="0 0 0" rpy="0 0 0" />
            <geometry>
                <mesh filename="package://moveo_urdf/meshes/Pivot_Arm_Gripper_Idol.STL" />
            </geometry>
            <material name="">
                <color rgba="0.79216 0.81961 0.93333 1" />
            </material>
        </visual>
        <collision>
            <origin xyz="0 0 0" rpy="0 0 0" />
            <geometry>
                <mesh filename="package://moveo_urdf/meshes/Pivot_Arm_Gripper_Idol_col.STL" />
            </geometry>
        </collision>
        
				<inertial>
            <mass value="0.1" />
            <inertia ixx="0.03" iyy="0.03" izz="0.03" ixy="0.0" ixz="0.0" iyz="0.0" />
        </inertial>

    </link>

    <joint name="Pivot_Arm_Gripper_Idol_Joint" type="revolute">
        <origin xyz="0.005 0 0.085" rpy="0 0 0" />
        <parent link="Link_5" />
        <child link="Pivot_Arm_Gripper_Idol" />
        <axis xyz="0 1 0" />
        <limit lower="-1.5707963268" upper="1.5707963268" effort="100" velocity="0.5" />
        <mimic joint="Gripper_Idol_Gear_Joint" multiplier="1" offset="0" />
    </joint>

  <gazebo reference="camera_depth_frame">
    <sensor name="camera" type="depth">
      <always_on>true</always_on>
      <update_rate>1.0</update_rate>
      <camera>
        <horizontal_fov>1.047</horizontal_fov>
        <image>
          <format>R8G8B8</format>
          <width>1280</width>
          <height>1024</height>
        </image>
        <clip>
          <near>0.05</near>
          <far>3.0</far>
        </clip>
      </camera>
      <plugin filename="libgazebo_ros_openni_kinect.so" name="camera_depth_frame_kinect_controller">
        <baseline>0.1</baseline>
        <alwaysOn>true</alwaysOn>
        <updateRate>1</updateRate>
        <cameraName>camera</cameraName>
        <imageTopicName>rgb/image_color</imageTopicName>
        <cameraInfoTopicName>rgb/camera_info</cameraInfoTopicName>
        <depthImageTopicName>depth_registered/image_raw</depthImageTopicName>
        <depthImageCameraInfoTopicName>depth_registered/camera_info</depthImageCameraInfoTopicName>
        <pointCloudTopicName>depth/points</pointCloudTopicName>
        <frameName>camera_depth_optical_frame</frameName>
        <pointCloudCutoff>0.05</pointCloudCutoff>
    	<distortionK1>0.00000001</distortionK1>
    	<distortionK2>0.00000001</distortionK2>
    	<distortionK3>0.00000001</distortionK3>
    	<distortionT1>0.00000001</distortionT1>
    	<distortionT2>0.00000001</distortionT2>
      </plugin>
    </sensor>
  </gazebo>

  <joint name="camera_rgb_joint" type="fixed">
    <origin rpy="0 0 -1.57" xyz="0.0 1.1 0.5"/>
    <parent link="world"/>
    <child link="camera_rgb_frame"/>
  </joint>
  <link name="camera_rgb_frame">
    <inertial>
      <mass value="0.001"/>
      <origin xyz="0 0 0"/>
      <inertia ixx="0.0001" ixy="0.0" ixz="0.0" iyy="0.0001" iyz="0.0" izz="0.0001"/>
    </inertial>
  </link>
  <joint name="camera_rgb_optical_joint" type="fixed">
    <origin rpy="-1.57079632679 0 -1.57079632679" xyz="0 0 0"/>
    <parent link="camera_rgb_frame"/>
    <child link="camera_rgb_optical_frame"/>
  </joint>
  <link name="camera_rgb_optical_frame">
    <inertial>
      <mass value="0.001"/>
      <origin xyz="0 0 0"/>
      <inertia ixx="0.0001" ixy="0.0" ixz="0.0" iyy="0.0001" iyz="0.0" izz="0.0001"/>
    </inertial>
  </link>
  <joint name="camera_joint" type="fixed">
    <origin rpy="0 0 0" xyz="-0.031 -0.0 -0.016"/>
    <parent link="camera_rgb_frame"/>
    <child link="camera_link"/>
  </joint>
  <link name="camera_link">
    <visual>
      <origin rpy="0 0 1.57079632679" xyz="0 0 0"/>
      <geometry>
        <mesh filename="package://moveo_urdf/meshes/kinect.dae"/>
      </geometry>
    </visual>
    <collision>
      <origin rpy="0 0 0" xyz="0.0 0.0 0.0"/>
      <geometry>
        <box size="0.07271 0.27794 0.073"/>
      </geometry>
    </collision>
    <inertial>
      <mass value="0.001"/>
      <origin xyz="0 0 0"/>
      <inertia ixx="0.0001" ixy="0.0" ixz="0.0" iyy="0.0001" iyz="0.0" izz="0.0001"/>
    </inertial>
  </link>

  <joint name="camera_depth_joint" type="fixed">
    <origin rpy="0 0 0" xyz="0 0.0 0"/>
    <parent link="camera_rgb_frame"/>
    <child link="camera_depth_frame"/>
  </joint>
  <link name="camera_depth_frame">
    <inertial>
      <mass value="0.001"/>
      <origin xyz="0 0 0"/>
      <inertia ixx="0.0001" ixy="0.0" ixz="0.0" iyy="0.0001" iyz="0.0" izz="0.0001"/>
    </inertial>
  </link>
  <joint name="camera_depth_optical_joint" type="fixed">
    <origin rpy="-1.57079632679 0 -1.57079632679" xyz="0 0 0"/>
    <parent link="camera_depth_frame"/>
    <child link="camera_depth_optical_frame"/>
  </joint>
  <link name="camera_depth_optical_frame">
    <inertial>
      <mass value="0.001"/>
      <origin xyz="0 0 0"/>
      <inertia ixx="0.0001" ixy="0.0" ixz="0.0" iyy="0.0001" iyz="0.0" izz="0.0001"/>
    </inertial>
  </link>


  <gazebo>
    <plugin filename="libgazebo_ros_control.so" name="gazebo_ros_control">
      <robotNamespace>/moveo_urdf</robotNamespace>
      <robotSimType>gazebo_ros_control/DefaultRobotHWSim</robotSimType>
    </plugin>
  </gazebo>

    <transmission name="trans1">
      <type>transmission_interface/SimpleTransmission</type>
      <joint name="Joint_1">
        <hardwareInterface>hardware_interface/EffortJointInterface</hardwareInterface>
      </joint>
      <actuator name="motor1">
        <mechanicalReduction>1</mechanicalReduction>
      </actuator>
    </transmission>

    <transmission name="trans2">
      <type>transmission_interface/SimpleTransmission</type>
      <joint name="Joint_2">
        <hardwareInterface>hardware_interface/EffortJointInterface</hardwareInterface>
      </joint>
      <actuator name="motor2">
        <mechanicalReduction>1</mechanicalReduction>
      </actuator>
    </transmission>

    <transmission name="trans3">
      <type>transmission_interface/SimpleTransmission</type>
      <joint name="Joint_3">
        <hardwareInterface>hardware_interface/EffortJointInterface</hardwareInterface>
      </joint>
      <actuator name="motor3">
        <mechanicalReduction>1</mechanicalReduction>
      </actuator>
    </transmission>

    <transmission name="trans4">
      <type>transmission_interface/SimpleTransmission</type>
      <joint name="Joint_4">
        <hardwareInterface>hardware_interface/EffortJointInterface</hardwareInterface>
      </joint>
      <actuator name="motor4">
        <mechanicalReduction>1</mechanicalReduction>
      </actuator>
    </transmission>

    <transmission name="trans5">
      <type>transmission_interface/SimpleTransmission</type>
      <joint name="Joint_5">
        <hardwareInterface>hardware_interface/EffortJointInterface</hardwareInterface>
      </joint>
      <actuator name="motor5">
        <mechanicalReduction>1</mechanicalReduction>
      </actuator>
    </transmission>

    <transmission name="trans6">
      <type>transmission_interface/SimpleTransmission</type>
      <joint name="Gripper_Servo_Gear_Joint">
        <hardwareInterface>hardware_interface/EffortJointInterface</hardwareInterface>
      </joint>
      <actuator name="motor6">
        <mechanicalReduction>1</mechanicalReduction>
      </actuator>
    </transmission>

    <transmission name="trans7">
      <type>transmission_interface/SimpleTransmission</type>
      <joint name="Gripper_Idol_Gear_Joint">
        <hardwareInterface>hardware_interface/EffortJointInterface</hardwareInterface>
      </joint>
      <actuator name="motor7">
        <mechanicalReduction>1</mechanicalReduction>
      </actuator>
    </transmission>

  <gazebo>

    <plugin filename="libroboticsgroup_gazebo_mimic_joint_plugin.so" name="mimic_moveo_1">
        <joint>Gripper_Servo_Gear_Joint</joint>
        <mimicJoint>Tip_Gripper_Servo_Joint</mimicJoint>
        <multiplier>1.0</multiplier>
        <offset>0.0</offset>
	<hasPID/>
    </plugin>


    <plugin filename="libroboticsgroup_gazebo_mimic_joint_plugin.so" name="mimic_moveo_2">
        <joint>Gripper_Idol_Gear_Joint</joint>
        <mimicJoint>Tip_Gripper_Idol_Joint</mimicJoint>
        <multiplier>-1.0</multiplier>
        <offset>0.0</offset>
<hasPID/>
    </plugin>


    <plugin filename="libroboticsgroup_gazebo_mimic_joint_plugin.so" name="mimic_moveo_3">
        <joint>Gripper_Servo_Gear_Joint</joint>
        <mimicJoint>Pivot_Arm_Gripper_Servo_Joint</mimicJoint>
        <multiplier>1.0</multiplier>
        <offset>0.0</offset>
<hasPID/>
    </plugin>


    <plugin filename="libroboticsgroup_gazebo_mimic_joint_plugin.so" name="mimic_moveo_4">
        <joint>Gripper_Idol_Gear_Joint</joint>
        <mimicJoint>Pivot_Arm_Gripper_Idol_Joint</mimicJoint>
        <multiplier>1.0</multiplier>
        <offset>0.0</offset>
<hasPID/>
</plugin>

</gazebo>

</robot>
